<?xml version="1.0"?>
<robot name="truck_urdf" xmlns:xacro="http://ros.org/wiki/xacro">

  <!-- ===== dummy static tf anchor (map -> dummy_link) ===== -->
  <link name="dummy_link">
    <inertial>
      <origin xyz="0 0 0" rpy="0 0 0"/>
      <mass value="0.01"/>
      <inertia ixx="1e-5" iyy="1e-5" izz="1e-5" ixy="0" ixz="0" iyz="0"/>
    </inertial>
  </link>
  <joint name="dummy_joint" type="fixed">
    <origin xyz="0 0 0" rpy="0 0 0"/>
    <parent link="dummy_link"/>
    <child link="base_link"/>
  </joint>

  <!-- ===== base_link ===== -->
  <link name="base_link">
    <inertial>
      <origin xyz="-0.254000016680143 -0.429384963721556 -0.393680147234163" rpy="0 0 0"/>
      <mass value="207.768846555119"/>
      <inertia ixx="19.5962917065594" ixy="-8.19943544895025E-07" ixz="-3.27401357177382E-07"
               iyy="9.3529571029121"  iyz="2.3242716663183"  izz="19.1468681302977"/>
    </inertial>
    <visual>
      <origin xyz="0 0 0" rpy="0 0 0"/>
      <geometry><mesh filename="package://project1phase1/meshes/base_link.STL"/></geometry>
      <material name="base_mat"><color rgba="0.79 0.82 0.93 1"/></material>
    </visual>
    <collision>
      <origin xyz="0 0 0" rpy="0 0 0"/>
      <geometry><mesh filename="package://project1phase1/meshes/base_link.STL"/></geometry>
    </collision>
  </link>

  <!-- ===== FRONT AXLE (steer + free axle roll per wheel) ===== -->
  <!-- FL hub has inertial so Gazebo keeps the joint -->
  <link name="wheel_fl_hub">
    <inertial>
      <origin xyz="0 0 0" rpy="0 0 0"/>
      <mass value="0.01"/>
      <inertia ixx="1e-5" iyy="1e-5" izz="1e-5" ixy="0" ixz="0" iyz="0"/>
    </inertial>
  </link>
  <joint name="wheel_fl_steer" type="revolute">
    <origin xyz="-0.0381 -0.2286 -0.1016" rpy="3.14159265358979 0 0"/>
    <parent link="base_link"/>
    <child  link="wheel_fl_hub"/>
    <axis xyz="0 0 -1"/>
    <limit lower="-0.65" upper="0.65" effort="50.0" velocity="2.0"/>
    <dynamics damping="0.1"/>
  </joint>

  <link name="wheel_fl">
    <inertial>
      <origin xyz="0 0 0" rpy="0 0 0"/>
      <mass value="1.5815"/>
      <inertia ixx="0.00863" iyy="0.00497" izz="0.00497" ixy="0" ixz="0" iyz="0"/>
    </inertial>
    <visual>
      <origin xyz="0 0 0" rpy="0 0 0"/>
      <geometry><mesh filename="package://project1phase1/meshes/wheel_fl.STL"/></geometry>
      <material name="wheel_fl_mat"><color rgba="0.79 0.82 0.93 1"/></material>
    </visual>
    <collision>
      <!-- cylinder axis (Z) rotated to align with axle X -->
      <origin xyz="0 0 0" rpy="0 1.57079632679 0"/>
      <geometry><cylinder radius="0.17" length="0.06"/></geometry>
      <surface>
        <contact><ode><kp>1e6</kp><kd>1.0</kd><max_vel>0.2</max_vel><min_depth>0.001</min_depth></ode></contact>
        <friction><ode><mu>1.2</mu><mu2>1.2</mu2><slip1>0.01</slip1><slip2>0.0</slip2></ode></friction>
      </surface>
    </collision>
  </link>
  <joint name="wheel_fl_axle" type="continuous">
    <origin xyz="0 0 0" rpy="0 0 0"/>
    <parent link="wheel_fl_hub"/>
    <child  link="wheel_fl"/>
    <axis xyz="1 0 0"/>
    <dynamics damping="0.05"/>
  </joint>

  <link name="wheel_fr_hub">
    <inertial>
      <origin xyz="0 0 0" rpy="0 0 0"/>
      <mass value="0.01"/>
      <inertia ixx="1e-5" iyy="1e-5" izz="1e-5" ixy="0" ixz="0" iyz="0"/>
    </inertial>
  </link>
  <joint name="wheel_fr_steer" type="revolute">
    <origin xyz="-0.4699 -0.2286 -0.1016" rpy="3.14159265358979 0 0"/>
    <parent link="base_link"/>
    <child  link="wheel_fr_hub"/>
    <axis xyz="0 0 -1"/>
    <limit lower="-0.65" upper="0.65" effort="50.0" velocity="2.0"/>
    <dynamics damping="0.1"/>
  </joint>

  <link name="wheel_fr">
    <inertial>
      <origin xyz="0 0 0" rpy="0 0 0"/>
      <mass value="1.5815"/>
      <inertia ixx="0.00863" iyy="0.00497" izz="0.00497" ixy="0" ixz="0" iyz="0"/>
    </inertial>
    <visual>
      <origin xyz="0 0 0" rpy="0 0 0"/>
      <geometry><mesh filename="package://project1phase1/meshes/wheel_fr.STL"/></geometry>
      <material name="wheel_fr_mat"><color rgba="0.79 0.82 0.93 1"/></material>
    </visual>
    <collision>
      <origin xyz="0 0 0" rpy="0 1.57079632679 0"/>
      <geometry><cylinder radius="0.17" length="0.06"/></geometry>
      <surface>
        <contact><ode><kp>1e6</kp><kd>1.0</kd><max_vel>0.2</max_vel><min_depth>0.001</min_depth></ode></contact>
        <friction><ode><mu>1.2</mu><mu2>1.2</mu2><slip1>0.01</slip1><slip2>0.0</slip2></ode></friction>
      </surface>
    </collision>
  </link>
  <joint name="wheel_fr_axle" type="continuous">
    <origin xyz="0 0 0" rpy="0 0 0"/>
    <parent link="wheel_fr_hub"/>
    <child  link="wheel_fr"/>
    <axis xyz="1 0 0"/>
    <dynamics damping="0.05"/>
  </joint>

  <!-- ===== REAR DRIVE WHEELS (continuous on X) ===== -->
  <link name="wheel_bl">
    <inertial>
      <origin xyz="0 0 0" rpy="0 0 0"/>
      <mass value="1.5815"/>
      <inertia ixx="0.00863" iyy="0.00497" izz="0.00497" ixy="0" ixz="0" iyz="0"/>
    </inertial>
    <visual><origin xyz="0 0 0" rpy="0 0 0"/><geometry>
      <mesh filename="package://project1phase1/meshes/wheel_bl.STL"/></geometry></visual>
    <collision>
      <origin xyz="0 0 0" rpy="0 1.57079632679 0"/>
      <geometry><cylinder radius="0.17" length="0.06"/></geometry>
      <surface>
        <contact><ode><kp>1e6</kp><kd>1.0</kd><max_vel>0.2</max_vel><min_depth>0.001</min_depth></ode></contact>
        <friction><ode><mu>1.2</mu><mu2>1.2</mu2><slip1>0.01</slip1><slip2>0.0</slip2></ode></friction>
      </surface>
    </collision>
  </link>
  <joint name="joint_bl" type="continuous">
    <origin xyz="-0.0381 -0.7366 -0.1016" rpy="3.14159265358979 0 0"/>
    <parent link="base_link"/>
    <child  link="wheel_bl"/>
    <axis xyz="1 0 0"/>
    <dynamics damping="0.1"/>
  </joint>

  <link name="wheel_br">
    <inertial>
      <origin xyz="0 0 0" rpy="0 0 0"/>
      <mass value="1.5815"/>
      <inertia ixx="0.00863" iyy="0.00497" izz="0.00497" ixy="0" ixz="0" iyz="0"/>
    </inertial>
    <visual><origin xyz="0 0 0" rpy="0 0 0"/><geometry>
      <mesh filename="package://project1phase1/meshes/wheel_br.STL"/></geometry></visual>
    <collision>
      <origin xyz="0 0 0" rpy="0 1.57079632679 0"/>
      <geometry><cylinder radius="0.17" length="0.06"/></geometry>
      <surface>
        <contact><ode><kp>1e6</kp><kd>1.0</kd><max_vel>0.2</max_vel><min_depth>0.001</min_depth></ode></contact>
        <friction><ode><mu>1.2</mu><mu2>1.2</mu2><slip1>0.01</slip1><slip2>0.0</slip2></ode></friction>
      </surface>
    </collision>
  </link>
  <joint name="joint_br" type="continuous">
    <origin xyz="-0.4699 -0.7366 -0.1016" rpy="3.14159265358979 0 0"/>
    <parent link="base_link"/>
    <child  link="wheel_br"/>
    <axis xyz="1 0 0"/>
    <dynamics damping="0.1"/>
  </joint>

  <!-- ===== FIRST TRAILER (hitch fixed) ===== -->
  <link name="trailer">
    <inertial>
      <origin xyz="3.69323682747336E-10 0.571256988776015 0.117353006753824" rpy="0 0 0"/>
      <mass value="154.484741148508"/>
      <inertia ixx="13.6421910845191" ixy="-2.48524307383535E-09" ixz="6.24243486154171E-09"
               iyy="4.71963963467751"  iyz="0.00663582007885279"  izz="15.5438252225012"/>
    </inertial>
    <visual><origin xyz="0 0 0" rpy="0 0 0"/><geometry>
      <mesh filename="package://project1phase1/meshes/trailer.STL"/></geometry></visual>
    <collision><origin xyz="0 0 0" rpy="0 0 0"/><geometry>
      <mesh filename="package://project1phase1/meshes/trailer.STL"/></geometry></collision>
  </link>
  <joint name="hitch" type="revolute">
  <!-- keep your original pose -->
  <origin xyz="-0.254000000000682 -1.06680000000062 -0.20320000000001"
          rpy="-3.14159265358979 0 -0.0250798506762473"/>
  <parent link="base_link"/>
  <child  link="trailer"/>
  <!-- yaw axis -->
  <axis xyz="0 0 1"/>
  <!-- turn limits (tweak as you like) -->
  <limit lower="-1.2" upper="1.2" effort="500.0" velocity="2.0"/>
  <!-- add some damping so it’s stable -->
  <dynamics damping="5.0" friction="0.0"/>
  </joint>

  <!-- Trailer wheels: all free-rolling (continuous, axle along X) -->
  <link name="wheel_tfl">
    <inertial><origin xyz="0 0 0" rpy="0 0 0"/><mass value="1.5815"/>
      <inertia ixx="0.00863" iyy="0.00497" izz="0.00497" ixy="0" ixz="0" iyz="0"/></inertial>
    <visual><origin xyz="0 0 0" rpy="0 0 0"/><geometry>
      <mesh filename="package://project1phase1/meshes/wheel_tfl.STL"/></geometry></visual>
    <collision>
      <origin xyz="0 0 0" rpy="0 1.57079632679 0"/>
      <geometry><cylinder radius="0.17" length="0.06"/></geometry>
      <surface>
        <contact><ode><kp>1e6</kp><kd>1.0</kd><max_vel>0.2</max_vel><min_depth>0.001</min_depth></ode></contact>
        <friction><ode><mu>1.0</mu><mu2>1.0</mu2><slip1>0.01</slip1><slip2>0.0</slip2></ode></friction>
      </surface>
    </collision>
  </link>
  <joint name="joint_tfl" type="continuous">
    <origin xyz="0.2159 0.31706871138665 -0.1016" rpy="0 0 0"/>
    <parent link="trailer"/><child link="wheel_tfl"/>
    <axis xyz="1 0 0"/><dynamics damping="0.05"/>
  </joint>

  <link name="wheel_tfr">
    <inertial><origin xyz="0 0 0" rpy="0 0 0"/><mass value="1.5815"/>
      <inertia ixx="0.00863" iyy="0.00497" izz="0.00497" ixy="0" ixz="0" iyz="0"/></inertial>
    <visual><origin xyz="0 0 0" rpy="0 0 0"/><geometry>
      <mesh filename="package://project1phase1/meshes/wheel_tfr.STL"/></geometry></visual>
    <collision>
      <origin xyz="0 0 0" rpy="0 1.57079632679 0"/>
      <geometry><cylinder radius="0.17" length="0.06"/></geometry>
      <surface>
        <contact><ode><kp>1e6</kp><kd>1.0</kd><max_vel>0.2</max_vel><min_depth>0.001</min_depth></ode></contact>
        <friction><ode><mu>1.0</mu><mu2>1.0</mu2><slip1>0.01</slip1><slip2>0.0</slip2></ode></friction>
      </surface>
    </collision>
  </link>
  <joint name="joint_tfr" type="continuous">
    <origin xyz="-0.2159 0.31706871138665 -0.1016" rpy="0 0 0"/>
    <parent link="trailer"/><child link="wheel_tfr"/>
    <axis xyz="1 0 0"/><dynamics damping="0.05"/>
  </joint>

  <link name="wheel_tbl">
    <inertial><origin xyz="0 0 0" rpy="0 0 0"/><mass value="1.5815"/>
      <inertia ixx="0.00863" iyy="0.00497" izz="0.00497" ixy="0" ixz="0" iyz="0"/></inertial>
    <visual><origin xyz="0 0 0" rpy="0 0 0"/><geometry>
      <mesh filename="package://project1phase1/meshes/wheel_tbl.STL"/></geometry></visual>
    <collision>
      <origin xyz="0 0 0" rpy="0 1.57079632679 0"/>
      <geometry><cylinder radius="0.17" length="0.06"/></geometry>
      <surface>
        <contact><ode><kp>1e6</kp><kd>1.0</kd><max_vel>0.2</max_vel><min_depth>0.001</min_depth></ode></contact>
        <friction><ode><mu>1.0</mu><mu2>1.0</mu2><slip1>0.01</slip1><slip2>0.0</slip2></ode></friction>
      </surface>
    </collision>
  </link>
  <joint name="joint_tbl" type="continuous">
    <origin xyz="0.2159 0.82506871138665 -0.1016" rpy="0 0 0"/>
    <parent link="trailer"/><child link="wheel_tbl"/>
    <axis xyz="1 0 0"/><dynamics damping="0.05"/>
  </joint>

  <link name="wheel_tbr">
    <inertial><origin xyz="0 0 0" rpy="0 0 0"/><mass value="1.5815"/>
      <inertia ixx="0.00863" iyy="0.00497" izz="0.00497" ixy="0" ixz="0" iyz="0"/></inertial>
    <visual><origin xyz="0 0 0" rpy="0 0 0"/><geometry>
      <mesh filename="package://project1phase1/meshes/wheel_tbr.STL"/></geometry></visual>
    <collision>
      <origin xyz="0 0 0" rpy="0 1.57079632679 0"/>
      <geometry><cylinder radius="0.17" length="0.06"/></geometry>
      <surface>
        <contact><ode><kp>1e6</kp><kd>1.0</kd><max_vel>0.2</max_vel><min_depth>0.001</min_depth></ode></contact>
        <friction><ode><mu>1.0</mu><mu2>1.0</mu2><slip1>0.01</slip1><slip2>0.0</slip2></ode></friction>
      </surface>
    </collision>
  </link>
  <joint name="joint_tbr" type="continuous">
    <origin xyz="-0.2159 0.82506871138665 -0.1016" rpy="0 0 0"/>
    <parent link="trailer"/><child link="wheel_tbr"/>
    <axis xyz="1 0 0"/><dynamics damping="0.05"/>
  </joint>

  <!-- ===== BACK TRAILER (fixed to front trailer) ===== -->
  <link name="back_trailer">
    <inertial>
      <origin xyz="3.6686853555068E-10 0.571256988777377 0.117353006753846" rpy="0 0 0"/>
      <mass value="154.484741148483"/>
      <inertia ixx="13.6421910845091" ixy="-2.52925029141024E-09" ixz="6.24522738612748E-09"
               iyy="4.71963963467603"  iyz="0.00663582007955939"  izz="15.5438252224907"/>
    </inertial>
    <visual><origin xyz="0 0 0" rpy="0 0 0"/><geometry>
      <mesh filename="package://project1phase1/meshes/back_trailer.STL"/></geometry></visual>
    <collision><origin xyz="0 0 0" rpy="0 0 0"/><geometry>
      <mesh filename="package://project1phase1/meshes/back_trailer.STL"/></geometry></collision>
  </link>
  <joint name="back_hitch" type="revolute">
  <origin xyz="0 1.15526871138527 0" rpy="0 0 -0.0257409734881418"/>
  <parent link="trailer"/>
  <child  link="back_trailer"/>
  <axis xyz="0 0 1"/>
  <limit lower="-1.2" upper="1.2" effort="500.0" velocity="2.0"/>
  <dynamics damping="5.0" friction="0.0"/>
  </joint>


  <!-- Back trailer wheels: free-rolling -->
  <link name="wheel_bfl">
    <inertial><origin xyz="0 0 0" rpy="0 0 0"/><mass value="1.5815"/>
      <inertia ixx="0.00863" iyy="0.00497" izz="0.00497" ixy="0" ixz="0" iyz="0"/></inertial>
    <visual><origin xyz="0 0 0" rpy="0 0 0"/><geometry>
      <mesh filename="package://project1phase1/meshes/wheel_bfl.STL"/></geometry></visual>
    <collision>
      <origin xyz="0 0 0" rpy="0 1.57079632679 0"/>
      <geometry><cylinder radius="0.17" length="0.06"/></geometry>
      <surface>
        <contact><ode><kp>1e6</kp><kd>1.0</kd><max_vel>0.2</max_vel><min_depth>0.001</min_depth></ode></contact>
        <friction><ode><mu>1.0</mu><mu2>1.0</mu2><slip1>0.01</slip1><slip2>0.0</slip2></ode></friction>
      </surface>
    </collision>
  </link>
  <joint name="joint_bfl" type="continuous">
    <origin xyz="0.2159 0.31706871138665 -0.1016" rpy="0 0 0"/>
    <parent link="back_trailer"/><child link="wheel_bfl"/>
    <axis xyz="1 0 0"/><dynamics damping="0.05"/>
  </joint>

  <link name="wheel_bfr">
    <inertial><origin xyz="0 0 0" rpy="0 0 0"/><mass value="1.5815"/>
      <inertia ixx="0.00863" iyy="0.00497" izz="0.00497" ixy="0" ixz="0" iyz="0"/></inertial>
    <visual><origin xyz="0 0 0" rpy="0 0 0"/><geometry>
      <mesh filename="package://project1phase1/meshes/wheel_bfr.STL"/></geometry></visual>
    <collision>
      <origin xyz="0 0 0" rpy="0 1.57079632679 0"/>
      <geometry><cylinder radius="0.17" length="0.06"/></geometry>
      <surface>
        <contact><ode><kp>1e6</kp><kd>1.0</kd><max_vel>0.2</max_vel><min_depth>0.001</min_depth></ode></contact>
        <friction><ode><mu>1.0</mu><mu2>1.0</mu2><slip1>0.01</slip1><slip2>0.0</slip2></ode></friction>
      </surface>
    </collision>
  </link>
  <joint name="joint_bfr" type="continuous">
    <origin xyz="-0.2159 0.31706871138665 -0.1016" rpy="0 0 0"/>
    <parent link="back_trailer"/><child link="wheel_bfr"/>
    <axis xyz="1 0 0"/><dynamics damping="0.05"/>
  </joint>

  <link name="wheel_bbl">
    <inertial><origin xyz="0 0 0" rpy="0 0 0"/><mass value="1.5815"/>
      <inertia ixx="0.00863" iyy="0.00497" izz="0.00497" ixy="0" ixz="0" iyz="0"/></inertial>
    <visual><origin xyz="0 0 0" rpy="0 0 0"/><geometry>
      <mesh filename="package://project1phase1/meshes/wheel_bbl.STL"/></geometry></visual>
    <collision>
      <origin xyz="0 0 0" rpy="0 1.57079632679 0"/>
      <geometry><cylinder radius="0.17" length="0.06"/></geometry>
      <surface>
        <contact><ode><kp>1e6</kp><kd>1.0</kd><max_vel>0.2</max_vel><min_depth>0.001</min_depth></ode></contact>
        <friction><ode><mu>1.0</mu><mu2>1.0</mu2><slip1>0.01</slip1><slip2>0.0</slip2></ode></friction>
      </surface>
    </collision>
  </link>
  <joint name="joint_bbl" type="continuous">
    <origin xyz="0.2159 0.82506871138665 -0.1016" rpy="0 0 0"/>
    <parent link="back_trailer"/><child link="wheel_bbl"/>
    <axis xyz="1 0 0"/><dynamics damping="0.05"/>
  </joint>

  <link name="wheel_bbr">
    <inertial><origin xyz="0 0 0" rpy="0 0 0"/><mass value="1.5815"/>
      <inertia ixx="0.00863" iyy="0.00497" izz="0.00497" ixy="0" ixz="0" iyz="0"/></inertial>
    <visual><origin xyz="0 0 0" rpy="0 0 0"/><geometry>
      <mesh filename="package://project1phase1/meshes/wheel_bbr.STL"/></geometry></visual>
    <collision>
      <origin xyz="0 0 0" rpy="0 1.57079632679 0"/>
      <geometry><cylinder radius="0.17" length="0.06"/></geometry>
      <surface>
        <contact><ode><kp>1e6</kp><kd>1.0</kd><max_vel>0.2</max_vel><min_depth>0.001</min_depth></ode></contact>
        <friction><ode><mu>1.0</mu><mu2>1.0</mu2><slip1>0.01</slip1><slip2>0.0</slip2></ode></friction>
      </surface>
    </collision>
  </link>
  <joint name="joint_bbr" type="continuous">
    <origin xyz="-0.2159 0.82506871138665 -0.1016" rpy="0 0 0"/>
    <parent link="back_trailer"/><child link="wheel_bbr"/>
    <axis xyz="1 0 0"/><dynamics damping="0.05"/>
  </joint>

  <!-- ===== LiDAR on a small mount link ===== -->
  <link name="lidar_link">
    <inertial><origin xyz="0 0 0" rpy="0 0 0"/><mass value="0.05"/>
      <inertia ixx="1e-5" iyy="1e-5" izz="1e-5" ixy="0" ixz="0" iyz="0"/></inertial>
    <visual><origin xyz="0 0 0" rpy="0 0 0"/><geometry>
      <cylinder radius="0.03" length="0.05"/></geometry></visual>
  </link>
  <joint name="lidar_mount" type="fixed">
    <origin xyz="0.00 0.00 0.35" rpy="0 0 0"/>
    <parent link="base_link"/>
    <child  link="lidar_link"/>
  </joint>

  <!-- ===== Gazebo Classic LiDAR plugin ===== -->
  <gazebo reference="lidar_link">
    <sensor name="lidar" type="ray">
      <pose>0.15 0.9 0 0 0 0</pose>
      <always_on>true</always_on>
      <visualize>true</visualize>
      <update_rate>10</update_rate>
      <ray>
        <scan><horizontal><samples>360</samples><resolution>1.0</resolution>
          <min_angle>0.0</min_angle><max_angle>6.28319</max_angle></horizontal></scan>
        <range><min>0.12</min><max>3.5</max><resolution>0.015</resolution></range>
        <noise><type>gaussian</type><mean>0.0</mean><stddev>0.01</stddev></noise>
      </ray>
      <plugin name="gazebo_ros_laser" filename="libgazebo_ros_ray_sensor.so">
        <ros><remapping>~/out:=scan</remapping></ros>
        <output_type>sensor_msgs/LaserScan</output_type>
        <frame_name>lidar_link</frame_name>
      </plugin>
    </sensor>
  </gazebo>

  <!-- ===== ros2_control (only controllable joints) ===== -->
  <ros2_control name="GazeboSystem" type="system">
    <hardware><plugin>gazebo_ros2_control/GazeboSystem</plugin></hardware>

    <!-- rear velocity control -->
    <joint name="joint_bl">
      <command_interface name="velocity"><param name="min">-1000.0</param><param name="max">1000.0</param></command_interface>
      <state_interface name="position"/><state_interface name="velocity"/>
    </joint>
    <joint name="joint_br">
      <command_interface name="velocity"><param name="min">-1000.0</param><param name="max">1000.0</param></command_interface>
      <state_interface name="position"/><state_interface name="velocity"/>
    </joint>

    <!-- front steering position control -->
    <joint name="wheel_fl_steer">
      <command_interface name="position"><param name="min">-3.14</param><param name="max">3.14</param></command_interface>
      <state_interface name="position"/><state_interface name="velocity"/>
    </joint>
    <joint name="wheel_fr_steer">
      <command_interface name="position"><param name="min">-3.14</param><param name="max">3.14</param></command_interface>
      <state_interface name="position"/><state_interface name="velocity"/>
    </joint>
  </ros2_control>

  <gazebo>
    <plugin name="gazebo_ros2_control" filename="libgazebo_ros2_control.so">
      <parameters>$(find project1phase1)/config/control.yaml</parameters>
    </plugin>
  </gazebo>

</robot>
